Workbook

Sheet Quarterly_Firm
A1: Quarter | B1: NetIncome | C1: TotalAssets_Begin | D1: TotalAssets_End | E1: OperatingCashFlow | F1: CurrentAssets | G1: CurrentLiabilities | H1: TotalDebt | I1: ShareholdersEquity | J1: HedgingDummy (0/1) | K1: IDRUSD_QuarterEnd | L1: AvgAssets | M1: ROA | N1: DER | O1: CurrentRatio | P1: ln_TotalAssets | Q1: OCF_to_AvgAssets
A2: 2013Q1 | B2: 11130 | C2: 2561947 | D2: 2490610 | E2: 393 | F2: 1300511 | G2: 1156561 | H2: 1004167 | I2: 1126840 | J2: 0 | K2: 9719 | L2: =AVERAGE(C2,D2) -> 2526278.5 | M2: =IFERROR(B2/L2,"") -> 0.00440569 | N2: =IFERROR(H2/I2,"") -> 0.89113539 | O2: =IFERROR(F2/G2,"") -> 1.1244638 | P2: =IFERROR(LN(D2),"") -> 14.728038 | Q2: =IFERROR(E2/L2,"") -> 0.0001555648
A3: 2013Q2 | B3: -6281 | C3: 2490610 | D3: 2670734 | E3: -158836 | F3: 1443524 | G3: 1354619 | H3: 1212390 | I3: 1120562 | J3: 0 | K3: 9929 | L3: =AVERAGE(C3,D3) -> 2580672 | M3: =IFERROR(B3/L3,"") -> -0.0024338622 | N3: =IFERROR(H3/I3,"") -> 1.0819482 | O3: =IFERROR(F3/G3,"") -> 1.065631 | P3: =IFERROR(LN(D3),"") -> 14.797864 | Q3: =IFERROR(E3/L3,"") -> -0.06154831
A4: 2013Q3 | B4: -47658 | C4: 2670734 | D4: 2452747 | E4: 164751 | F4: 1166651 | G4: 1143380 | H4: 1064788 | I4: 1072901 | J4: 1 | K4: 11613 | L4: =AVERAGE(C4,D4) -> 2561740.5 | M4: =IFERROR(B4/L4,"") -> -0.018603758 | N4: =IFERROR(H4/I4,"") -> 0.99243826 | O4: =IFERROR(F4/G4,"") -> 1.0203528 | P4: =IFERROR(LN(D4),"") -> 14.712719 | Q4: =IFERROR(E4/L4,"") -> 0.064312135
A5: 2013Q4 | B5: -21109 | C5: 2452747 | D5: 2383207 | E5: 132567 | F5: 1095219 | G5: 1138147 | H5: 1014767 | I5: 1046979 | J5: 1 | K5: 12189 | L5: =AVERAGE(C5,D5) -> 2417977 | M5: =IFERROR(B5/L5,"") -> -0.0087300251 | N5: =IFERROR(H5/I5,"") -> 0.96923338 | O5: =IFERROR(F5/G5,"") -> 0.96228255 | P5: =IFERROR(LN(D5),"") -> 14.683958 | Q5: =IFERROR(E5/L5,"") -> 0.054825584
A6: 2014Q1 | B6: -73521 | C6: 2383207 | D6: 2331037 | E6: 46168 | F6: 1040259 | G6: 1082181 | H6: 1044709 | I6: 979257 | J6: 1 | K6: 11404 | L6: =AVERAGE(C6,D6) -> 2357122 | M6: =IFERROR(B6/L6,"") -> -0.031191003 | N6: =IFERROR(H6/I6,"") -> 1.0668384 | O6: =IFERROR(F6/G6,"") -> 0.96126156 | P6: =IFERROR(LN(D6),"") -> 14.661824 | Q6: =IFERROR(E6/L6,"") -> 0.019586598
A7: 2014Q2 | B7: -17863 | C7: 2331037 | D7: 2569386 | E7: -104572 | F7: 1218381 | G7: 1343219 | H7: 1214853 | I7: 962016 | J7: 1 | K7: 11969 | L7: =AVERAGE(C7,D7) -> 2450211.5 | M7: =IFERROR(B7/L7,"") -> -0.0072903911 | N7: =IFERROR(H7/I7,"") -> 1.26282 | O7: =IFERROR(F7/G7,"") -> 0.90706058 | P7: =IFERROR(LN(D7),"") -> 14.759178 | Q7: =IFERROR(E7/L7,"") -> -0.042678765
A8: 2014Q3 | B8: -23413 | C8: 2569386 | D8: 2601200 | E8: -28874 | F8: 1224205 | G8: 1352036 | H8: 1341654 | I8: 939136 | J8: 1 | K8: 12212 | L8: =AVERAGE(C8,D8) -> 2585293 | M8: =IFERROR(B8/L8,"") -> -0.0090562269 | N8: =IFERROR(H8/I8,"") -> 1.4286046 | O8: =IFERROR(F8/G8,"") -> 0.90545296 | P8: =IFERROR(LN(D8),"") -> 14.771483 | Q8: =IFERROR(E8/L8,"") -> -0.01116856
A9: 2014Q4 | B9: -45507 | C9: 2601200 | D9: 2604357 | E9: 84980 | F9: 1058623 | G9: 1413295 | H9: 1346760 | I9: 885933 | J9: 1 | K9: 12440 | L9: =AVERAGE(C9,D9) -> 2602778.5 | M9: =IFERROR(B9/L9,"") -> -0.017484008 | N9: =IFERROR(H9/I9,"") -> 1.5201601 | O9: =IFERROR(F9/G9,"") -> 0.74904602 | P9: =IFERROR(LN(D9),"") -> 14.772696 | Q9: =IFERROR(E9/L9,"") -> 0.032649724
A10: 2015Q1 | B10: -46566 | C10: 2604357 | D10: 2671202 | E10: -61930 | F10: 1107587 | G10: 1512301 | H10: 1525533 | I10: 834853 | J10: 1 | K10: 13084 | L10: =AVERAGE(C10,D10) -> 2637779.5 | M10: =IFERROR(B10/L10,"") -> -0.017653485 | N10: =IFERROR(H10/I10,"") -> 1.8273073 | O10: =IFERROR(F10/G10,"") -> 0.73238529 | P10: =IFERROR(LN(D10),"") -> 14.798039 | Q10: =IFERROR(E10/L10,"") -> -0.023478081
A11: 2015Q2 | B11: -105213 | C11: 2671202 | D11: 2525491 | E11: 40323 | F11: 882748 | G11: 1491510 | H11: 1495880 | I11: 734154 | J11: 1 | K11: 13332 | L11: =AVERAGE(C11,D11) -> 2598346.5 | M11: =IFERROR(B11/L11,"") -> -0.04049229 | N11: =IFERROR(H11/I11,"") -> 2.0375562 | O11: =IFERROR(F11/G11,"") -> 0.59184853 | P11: =IFERROR(LN(D11),"") -> 14.741946 | Q11: =IFERROR(E11/L11,"") -> 0.015518715
A12: 2015Q3 | B12: 1060706 | C12: 2525491 | D12: 3545227 | E12: 21499 | F12: 844116 | G12: 1423396 | H12: 1425155 | I12: 1794862 | J12: 1 | K12: 14657 | L12: =AVERAGE(C12,D12) -> 3035359 | M12: =IFERROR(B12/L12,"") -> 0.34944993 | N12: =IFERROR(H12/I12,"") -> 0.79401926 | O12: =IFERROR(F12/G12,"") -> 0.59302963 | P12: =IFERROR(LN(D12),"") -> 15.081113 | Q12: =IFERROR(E12/L12,"") -> 0.0070828525
A13: 2015Q4 | B13: -6756 | C13: 3545227 | D13: 3702144 | E13: -73814 | F13: 892290 | G13: 1465327 | H13: 1627989 | I13: 1788029 | J13: 1 | K13: 13795 | L13: =AVERAGE(C13,D13) -> 3623685.5 | M13: =IFERROR(B13/L13,"") -> -0.0018644002 | N13: =IFERROR(H13/I13,"") -> 0.91049362 | O13: =IFERROR(F13/G13,"") -> 0.60893575 | P13: =IFERROR(LN(D13),"") -> 15.124423 | Q13: =IFERROR(E13/L13,"") -> -0.020369869
... A51: 2025Q2 | B51: -43393 | C51: 2918457 | D51: 2912334 | E51: -21847 | F51: 630998 | G51: 2306176 | H51: 1988966 | I51: 377717 | J51: 0 | K51: 16233 | L51: =AVERAGE(C51,D51) -> 2915395.5 | M51: =IFERROR(B51/L51,"") -> -0.014884087 | N51: =IFERROR(H51/I51,"") -> 5.2657572 | O51: =IFERROR(F51/G51,"") -> 0.27361225 | P51: =IFERROR(LN(D51),"") -> 14.884465 | Q51: =IFERROR(E51/L51,"") -> -0.007493666

Sheet FX_Calc
A1: Quarter | B1: IDRUSD_QuarterEnd | C1: lnE | D1: r_t (Quarterly log return) | E1: ERVol_4Q (SD of r) | F1: ERVol_12Q (SD of r)
A2: 2010Q1 | B2: 9083 | C2: =IFERROR(LN(B2),"") -> 9.1141598 | D2: =IF(ROW()>2,IFERROR(C2-C1,""),"")
A3: 2010Q2 | B3: 9058 | C3: =IFERROR(LN(B3),"") -> 9.1114036 | D3: =IF(ROW()>2,IFERROR(C3-C2,""),"") -> -0.0027561894
A4: 2010Q3 | B4: 8929 | C4: =IFERROR(LN(B4),"") -> 9.0970597 | D4: =IF(ROW()>2,IFERROR(C4-C3,""),"") -> -0.014343939
A5: 2010Q4 | B5: 9009 | C5: =IFERROR(LN(B5),"") -> 9.1059794 | D5: =IF(ROW()>2,IFERROR(C5-C4,""),"") -> 0.0089196711
A6: 2011Q1 | B6: 8709 | C6: =IFERROR(LN(B6),"") -> 9.0721123 | D6: =IF(ROW()>2,IFERROR(C6-C5,""),"") -> -0.033867104
A7: 2011Q2 | B7: 8597 | C7: =IFERROR(LN(B7),"") -> 9.0591686 | D7: =IF(ROW()>2,IFERROR(C7-C6,""),"") -> -0.012943669
A8: 2011Q3 | B8: 8823 | C8: =IFERROR(LN(B8),"") -> 9.0851172 | D8: =IF(ROW()>2,IFERROR(C8-C7,""),"") -> 0.025948643
A9: 2011Q4 | B9: 9068 | C9: =IFERROR(LN(B9),"") -> 9.112507 | D9: =IF(ROW()>2,IFERROR(C9-C8,""),"") -> 0.027389784
A10: 2012Q1 | B10: =Daily_FX!B92 -> 9180 | C10: =IFERROR(LN(B10),"") -> 9.1247825 | D10: =IF(ROW()>2,IFERROR(C10-C9,""),"") -> 0.012275472
A11: 2012Q2 | B11: =Daily_FX!B183 -> 9480 | C11: =IFERROR(LN(B11),"") -> 9.1569396 | D11: =IF(ROW()>2,IFERROR(C11-C10,""),"") -> 0.032157112
A12: 2012Q3 | B12: =Daily_FX!B275 -> 9588 | C12: =IFERROR(LN(B12),"") -> 9.1682676 | D12: =IF(ROW()>2,IFERROR(C12-C11,""),"") -> 0.011328
A13: 2012Q4 | B13: =Daily_FX!B367 -> 9670 | C13: =IFERROR(LN(B13),"") -> 9.1767836 | D13: =IF(ROW()>2,IFERROR(C13-C12,""),"") -> 0.0085159929
A14: =Quarterly_Firm!A2 -> 2013Q1 | B14: =Quarterly_Firm!K2 -> 9719 | C14: =IFERROR(LN(B14),"") -> 9.181838 | D14: =IF(ROW()>2,IFERROR(C14-C13,""),"") -> 0.0050544231 | E14: =IF(ROW()>=5,_xlfn.STDEV.S(OFFSET(D14,-3,0,4,1)),NA()) -> 0.012201631 | F14: =IF(ROW()>=13,_xlfn.STDEV.S(OFFSET(D14,-11,0,12,1)),NA()) -> 0.019212738
A15: =Quarterly_Firm!A3 -> 2013Q2 | B15: =Quarterly_Firm!K3 -> 9929 | C15: =IFERROR(LN(B15),"") -> 9.203215 | D15: =IF(ROW()>2,IFERROR(C15-C14,""),"") -> 0.021377036 | E15: =IF(ROW()>=5,_xlfn.STDEV.S(OFFSET(D15,-3,0,4,1)),NA()) -> 0.0070241537 | F15: =IF(ROW()>=13,_xlfn.STDEV.S(OFFSET(D15,-11,0,12,1)),NA()) -> 0.019514688
A16: =Quarterly_Firm!A4 -> 2013Q3 | B16: =Quarterly_Firm!K4 -> 11613 | C16: =IFERROR(LN(B16),"") -> 9.3598804 | D16: =IF(ROW()>2,IFERROR(C16-C15,""),"") -> 0.15666539 | E16: =IF(ROW()>=5,_xlfn.STDEV.S(OFFSET(D16,-3,0,4,1)),NA()) -> 0.072847378 | F16: =IF(ROW()>=13,_xlfn.STDEV.S(OFFSET(D16,-11,0,12,1)),NA()) -> 0.046194811
A17: =Quarterly_Firm!A5 -> 2013Q4 | B17: =Quarterly_Firm!K5 -> 12189 | C17: =IFERROR(LN(B17),"") -> 9.4082892 | D17: =IF(ROW()>2,IFERROR(C17-C16,""),"") -> 0.048408745 | E17: =IF(ROW()>=5,_xlfn.STDEV.S(OFFSET(D17,-3,0,4,1)),NA()) -> 0.068242866 | F17: =IF(ROW()>=13,_xlfn.STDEV.S(OFFSET(D17,-11,0,12,1)),NA()) -> 0.046590776
A18: =Quarterly_Firm!A6 -> 2014Q1 | B18: =Quarterly_Firm!K6 -> 11404 | C18: =IFERROR(LN(B18),"") -> 9.3417195 | D18: =IF(ROW()>2,IFERROR(C18-C17,""),"") -> -0.066569735 | E18: =IF(ROW()>=5,_xlfn.STDEV.S(OFFSET(D18,-3,0,4,1)),NA()) -> 0.091988116 | F18: =IF(ROW()>=13,_xlfn.STDEV.S(OFFSET(D18,-11,0,12,1)),NA()) -> 0.051097814
A19: =Quarterly_Firm!A7 -> 2014Q2 | B19: =Quarterly_Firm!K7 -> 11969 | C19: =IFERROR(LN(B19),"") -> 9.3900753 | D19: =IF(ROW()>2,IFERROR(C19-C18,""),"") -> 0.048355803 | E19: =IF(ROW()>=5,_xlfn.STDEV.S(OFFSET(D19,-3,0,4,1)),NA()) -> 0.091155693 | F19: =IF(ROW()>=13,_xlfn.STDEV.S(OFFSET(D19,-11,0,12,1)),NA()) -> 0.050293683
A20: =Quarterly_Firm!A8 -> 2014Q3 | B20: =Quarterly_Firm!K8 -> 12212 | C20: =IFERROR(LN(B20),"") -> 9.4101744 | D20: =IF(ROW()>2,IFERROR(C20-C19,""),"") -> 0.020099101 | E20: =IF(ROW()>=5,_xlfn.STDEV.S(OFFSET(D20,-3,0,4,1)),NA()) -> 0.054420659 | F20: =IF(ROW()>=13,_xlfn.STDEV.S(OFFSET(D20,-11,0,12,1)),NA()) -> 0.050339212
A21: =Quarterly_Firm!A9 -> 2014Q4 | B21: =Quarterly_Firm!K9 -> 12440 | C21: =IFERROR(LN(B21),"") -> 9.4286724 | D21: =IF(ROW()>2,IFERROR(C21-C20,""),"") -> 0.018498012 | E21: =IF(ROW()>=5,_xlfn.STDEV.S(OFFSET(D21,-3,0,4,1)),NA()) -> 0.04970612 | F21: =IF(ROW()>=13,_xlfn.STDEV.S(OFFSET(D21,-11,0,12,1)),NA()) -> 0.050399773
A22: =Quarterly_Firm!A10 -> 2015Q1 | B22: =Quarterly_Firm!K10 -> 13084 | C22: =IFERROR(LN(B22),"") -> 9.4791454 | D22: =IF(ROW()>2,IFERROR(C22-C21,""),"") -> 0.050473022 | E22: =IF(ROW()>=5,_xlfn.STDEV.S(OFFSET(D22,-3,0,4,1)),NA()) -> 0.017421135 | F22: =IF(ROW()>=13,_xlfn.STDEV.S(OFFSET(D22,-11,0,12,1)),NA()) -> 0.050635928
A23: =Quarterly_Firm!A11 -> 2015Q2 | B23: =Quarterly_Firm!K11 -> 13332 | C23: =IFERROR(LN(B23),"") -> 9.4979224 | D23: =IF(ROW()>2,IFERROR(C23-C22,""),"") -> 0.018777051 | E23: =IF(ROW()>=5,_xlfn.STDEV.S(OFFSET(D23,-3,0,4,1)),NA()) -> 0.0156897 | F23: =IF(ROW()>=13,_xlfn.STDEV.S(OFFSET(D23,-11,0,12,1)),NA()) -> 0.050720071
A24: =Quarterly_Firm!A12 -> 2015Q3 | B24: =Quarterly_Firm!K12 -> 14657 | C24: =IFERROR(LN(B24),"") -> 9.5926733 | D24: =IF(ROW()>2,IFERROR(C24-C23,""),"") -> 0.094750877 | E24: =IF(ROW()>=5,_xlfn.STDEV.S(OFFSET(D24,-3,0,4,1)),NA()) -> 0.036025643 | F24: =IF(ROW()>=13,_xlfn.STDEV.S(OFFSET(D24,-11,0,12,1)),NA()) -> 0.053789384
A25: =Quarterly_Firm!A13 -> 2015Q4 | B25: =Quarterly_Firm!K13 -> 13795 | C25: =IFERROR(LN(B25),"") -> 9.5320615 | D25: =IF(ROW()>2,IFERROR(C25-C24,""),"") -> -0.060611829 | E25: =IF(ROW()>=5,_xlfn.STDEV.S(OFFSET(D25,-3,0,4,1)),NA()) -> 0.065521748 | F25: =IF(ROW()>=13,_xlfn.STDEV.S(OFFSET(D25,-11,0,12,1)),NA()) -> 0.060241208
... A63: =Quarterly_Firm!A51 -> 2025Q2 | B63: =Quarterly_Firm!K51 -> 16233 | C63: =IFERROR(LN(B63),"") -> 9.6948015 | D63: =IF(ROW()>2,IFERROR(C63-C62,""),"") -> -0.021633335 | E63: =IF(ROW()>=5,_xlfn.STDEV.S(OFFSET(D63,-3,0,4,1)),NA()) -> 0.063283295 | F63: =IF(ROW()>=13,_xlfn.STDEV.S(OFFSET(D63,-11,0,12,1)),NA()) -> 0.039631306

Sheet CFV_Calc
A1: Quarter | B1: OperatingCashFlow | C1: AvgAssets | D1: OCF_to_AvgAssets | E1: ΔOCF | F1: CFV_4Q_SD(OCF/Assets) | G1: CFV_12Q_SD(OCF/Assets) | H1: CFV_4Q_SD(ΔOCF) | I1: CFV_12Q_SD(ΔOCF)
A2: 2008Q4 | B2: 55078 | C2: 1201644.3 | D2: =IFERROR(B2/C2,"") -> 0.045835526
A3: 2009Q4 | B3: 93727 | C3: 1494441.9 | D3: =IFERROR(B3/C3,"") -> 0.062717058 | E3: =IF(ROW()>2,IFERROR(B3-B2,""),"") -> 38649
A4: 20101H | B4: 104048 | C4: 1442896 | D4: =IFERROR(B4/C4,"") -> 0.072110533 | E4: =IF(ROW()>2,IFERROR(B4-B3,""),"") -> 10321
A5: 20102H | B5: 6191 | C5: 1704071.9 | D5: =IFERROR(B5/C5,"") -> 0.0036330626 | E5: =IF(ROW()>2,IFERROR(B5-B4,""),"") -> -97857
A6: 2011Q1 | B6: 16649 | C6: 2030297.6 | D6: =IFERROR(B6/C6,"") -> 0.0082002758 | E6: =IF(ROW()>2,IFERROR(B6-B5,""),"") -> 10458
A7: 2011Q2 | B7: 22174 | C7: 2201308.4 | D7: =IFERROR(B7/C7,"") -> 0.0100731 | E7: =IF(ROW()>2,IFERROR(B7-B6,""),"") -> 5525
A8: 2011Q3 | B8: -98923 | C8: 2312095.9 | D8: =IFERROR(B8/C8,"") -> -0.04278499 | E8: =IF(ROW()>2,IFERROR(B8-B7,""),"") -> -121097
A9: 2011Q4 | B9: 122368 | C9: 2373787.9 | D9: =IFERROR(B9/C9,"") -> 0.051549676 | E9: =IF(ROW()>2,IFERROR(B9-B8,""),"") -> 221291
A10: 2012Q1 | B10: -57868 | C10: 2346487.6 | D10: =IFERROR(B10/C10,"") -> -0.024661541 | E10: =IF(ROW()>2,IFERROR(B10-B9,""),"") -> -180236
A11: 2012Q2 | B11: 7731 | C11: 2360209.3 | D11: =IFERROR(B11/C11,"") -> 0.0032755569 | E11: =IF(ROW()>2,IFERROR(B11-B10,""),"") -> 65599
A12: 2012Q3 | B12: -97009 | C12: 2427810.6 | D12: =IFERROR(B12/C12,"") -> -0.039957399 | E12: =IF(ROW()>2,IFERROR(B12-B11,""),"") -> -104740
A13: 2012Q4 | B13: 167594 | C13: 2500001.3 | D13: =IFERROR(B13/C13,"") -> 0.067037564 | E13: =IF(ROW()>2,IFERROR(B13-B12,""),"") -> 264603
A14: =Quarterly_Firm!A2 -> 2013Q1 | B14: =Quarterly_Firm!E2 -> 393 | C14: =Quarterly_Firm!L2 -> 2526278.5 | D14: =Quarterly_Firm!Q2 -> 0.0001555648 | E14: =IF(ROW()>2,IFERROR(B14-B13,""),"") -> -167201 | F14: =IF(ROW()>=5,_xlfn.STDEV.S(OFFSET(D14,-3,0,4,1)),NA()) -> 0.044229129 | G14: =IF(ROW()>=13,_xlfn.STDEV.S(OFFSET(D14,-11,0,12,1)),NA()) -> 0.040526172 | H14: =IF(ROW()>=5,_xlfn.STDEV.S(OFFSET(E14,-3,0,4,1)),NA()) -> 193559.67 | I14: =IF(ROW()>=13,_xlfn.STDEV.S(OFFSET(E14,-11,0,12,1)),NA()) -> 141559.75
A15: =Quarterly_Firm!A3 -> 2013Q2 | B15: =Quarterly_Firm!E3 -> -158836 | C15: =Quarterly_Firm!L3 -> 2580672 | D15: =Quarterly_Firm!Q3 -> -0.06154831 | E15: =IF(ROW()>2,IFERROR(B15-B14,""),"") -> -159229 | F15: =IF(ROW()>=5,_xlfn.STDEV.S(OFFSET(D15,-3,0,4,1)),NA()) -> 0.056522884 | G15: =IF(ROW()>=13,_xlfn.STDEV.S(OFFSET(D15,-11,0,12,1)),NA()) -> 0.042834563 | H15: =IF(ROW()>=5,_xlfn.STDEV.S(OFFSET(E15,-3,0,4,1)),NA()) -> 206041.36 | I15: =IF(ROW()>=13,_xlfn.STDEV.S(OFFSET(E15,-11,0,12,1)),NA()) -> 147470.93
A16: =Quarterly_Firm!A4 -> 2013Q3 | B16: =Quarterly_Firm!E4 -> 164751 | C16: =Quarterly_Firm!L4 -> 2561740.5 | D16: =Quarterly_Firm!Q4 -> 0.064312135 | E16: =IF(ROW()>2,IFERROR(B16-B15,""),"") -> 323587 | F16: =IF(ROW()>=5,_xlfn.STDEV.S(OFFSET(D16,-3,0,4,1)),NA()) -> 0.061086852 | G16: =IF(ROW()>=13,_xlfn.STDEV.S(OFFSET(D16,-11,0,12,1)),NA()) -> 0.04175148 | H16: =IF(ROW()>=5,_xlfn.STDEV.S(OFFSET(E16,-3,0,4,1)),NA()) -> 265143.84 | I16: =IF(ROW()>=13,_xlfn.STDEV.S(OFFSET(E16,-11,0,12,1)),NA()) -> 178079.42
A17: =Quarterly_Firm!A5 -> 2013Q4 | B17: =Quarterly_Firm!E5 -> 132567 | C17: =Quarterly_Firm!L5 -> 2417977 | D17: =Quarterly_Firm!Q5 -> 0.054825584 | E17: =IF(ROW()>2,IFERROR(B17-B16,""),"") -> -32184 | F17: =IF(ROW()>=5,_xlfn.STDEV.S(OFFSET(D17,-3,0,4,1)),NA()) -> 0.058012911 | G17: =IF(ROW()>=13,_xlfn.STDEV.S(OFFSET(D17,-11,0,12,1)),NA()) -> 0.044327421 | H17: =IF(ROW()>=5,_xlfn.STDEV.S(OFFSET(E17,-3,0,4,1)),NA()) -> 230034.55 | I17: =IF(ROW()>=13,_xlfn.STDEV.S(OFFSET(E17,-11,0,12,1)),NA()) -> 175621.25
A18: =Quarterly_Firm!A6 -> 2014Q1 | B18: =Quarterly_Firm!E6 -> 46168 | C18: =Quarterly_Firm!L6 -> 2357122 | D18: =Quarterly_Firm!Q6 -> 0.019586598 | E18: =IF(ROW()>2,IFERROR(B18-B17,""),"") -> -86399 | F18: =IF(ROW()>=5,_xlfn.STDEV.S(OFFSET(D18,-3,0,4,1)),NA()) -> 0.057226715 | G18: =IF(ROW()>=13,_xlfn.STDEV.S(OFFSET(D18,-11,0,12,1)),NA()) -> 0.044464499 | H18: =IF(ROW()>=5,_xlfn.STDEV.S(OFFSET(E18,-3,0,4,1)),NA()) -> 214506.55 | I18: =IF(ROW()>=13,_xlfn.STDEV.S(OFFSET(E18,-11,0,12,1)),NA()) -> 177836.69
A19: =Quarterly_Firm!A7 -> 2014Q2 | B19: =Quarterly_Firm!E7 -> -104572 | C19: =Quarterly_Firm!L7 -> 2450211.5 | D19: =Quarterly_Firm!Q7 -> -0.042678765 | E19: =IF(ROW()>2,IFERROR(B19-B18,""),"") -> -150740 | F19: =IF(ROW()>=5,_xlfn.STDEV.S(OFFSET(D19,-3,0,4,1)),NA()) -> 0.048445227 | G19: =IF(ROW()>=13,_xlfn.STDEV.S(OFFSET(D19,-11,0,12,1)),NA()) -> 0.046837925 | H19: =IF(ROW()>=5,_xlfn.STDEV.S(OFFSET(E19,-3,0,4,1)),NA()) -> 212285.61 | I19: =IF(ROW()>=13,_xlfn.STDEV.S(OFFSET(E19,-11,0,12,1)),NA()) -> 183231.27
A20: =Quarterly_Firm!A8 -> 2014Q3 | B20: =Quarterly_Firm!E8 -> -28874 | C20: =Quarterly_Firm!L8 -> 2585293 | D20: =Quarterly_Firm!Q8 -> -0.01116856 | E20: =IF(ROW()>2,IFERROR(B20-B19,""),"") -> 75698 | F20: =IF(ROW()>=5,_xlfn.STDEV.S(OFFSET(D20,-3,0,4,1)),NA()) -> 0.041753103 | G20: =IF(ROW()>=13,_xlfn.STDEV.S(OFFSET(D20,-11,0,12,1)),NA()) -> 0.044806448 | H20: =IF(ROW()>=5,_xlfn.STDEV.S(OFFSET(E20,-3,0,4,1)),NA()) -> 95883.039 | I20: =IF(ROW()>=13,_xlfn.STDEV.S(OFFSET(E20,-11,0,12,1)),NA()) -> 181234.7
A21: =Quarterly_Firm!A9 -> 2014Q4 | B21: =Quarterly_Firm!E9 -> 84980 | C21: =Quarterly_Firm!L9 -> 2602778.5 | D21: =Quarterly_Firm!Q9 -> 0.032649724 | E21: =IF(ROW()>2,IFERROR(B21-B20,""),"") -> 113854 | F21: =IF(ROW()>=5,_xlfn.STDEV.S(OFFSET(D21,-3,0,4,1)),NA()) -> 0.033641265 | G21: =IF(ROW()>=13,_xlfn.STDEV.S(OFFSET(D21,-11,0,12,1)),NA()) -> 0.043397692 | H21: =IF(ROW()>=5,_xlfn.STDEV.S(OFFSET(E21,-3,0,4,1)),NA()) -> 126904.33 | I21: =IF(ROW()>=13,_xlfn.STDEV.S(OFFSET(E21,-11,0,12,1)),NA()) -> 172044.29
A22: =Quarterly_Firm!A10 -> 2015Q1 | B22: =Quarterly_Firm!E10 -> -61930 | C22: =Quarterly_Firm!L10 -> 2637779.5 | D22: =Quarterly_Firm!Q10 -> -0.023478081 | E22: =IF(ROW()>2,IFERROR(B22-B21,""),"") -> -146910 | F22: =IF(ROW()>=5,_xlfn.STDEV.S(OFFSET(D22,-3,0,4,1)),NA()) -> 0.031960702 | G22: =IF(ROW()>=13,_xlfn.STDEV.S(OFFSET(D22,-11,0,12,1)),NA()) -> 0.043325064 | H22: =IF(ROW()>=5,_xlfn.STDEV.S(OFFSET(E22,-3,0,4,1)),NA()) -> 141511.74 | I22: =IF(ROW()>=13,_xlfn.STDEV.S(OFFSET(E22,-11,0,12,1)),NA()) -> 169170.24
A23: =Quarterly_Firm!A11 -> 2015Q2 | B23: =Quarterly_Firm!E11 -> 40323 | C23: =Quarterly_Firm!L11 -> 2598346.5 | D23: =Quarterly_Firm!Q11 -> 0.015518715 | E23: =IF(ROW()>2,IFERROR(B23-B22,""),"") -> 102253 | F23: =IF(ROW()>=5,_xlfn.STDEV.S(OFFSET(D23,-3,0,4,1)),NA()) -> 0.025410511 | G23: =IF(ROW()>=13,_xlfn.STDEV.S(OFFSET(D23,-11,0,12,1)),NA()) -> 0.043418373 | H23: =IF(ROW()>=5,_xlfn.STDEV.S(OFFSET(E23,-3,0,4,1)),NA()) -> 123129.34 | I23: =IF(ROW()>=13,_xlfn.STDEV.S(OFFSET(E23,-11,0,12,1)),NA()) -> 170792.16
A24: =Quarterly_Firm!A12 -> 2015Q3 | B24: =Quarterly_Firm!E12 -> 21499 | C24: =Quarterly_Firm!L12 -> 3035359 | D24: =Quarterly_Firm!Q12 -> 0.0070828525 | E24: =IF(ROW()>2,IFERROR(B24-B23,""),"") -> -18824 | F24: =IF(ROW()>=5,_xlfn.STDEV.S(OFFSET(D24,-3,0,4,1)),NA()) -> 0.02349353 | G24: =IF(ROW()>=13,_xlfn.STDEV.S(OFFSET(D24,-11,0,12,1)),NA()) -> 0.040916634 | H24: =IF(ROW()>=5,_xlfn.STDEV.S(OFFSET(E24,-3,0,4,1)),NA()) -> 122094.14 | I24: =IF(ROW()>=13,_xlfn.STDEV.S(OFFSET(E24,-11,0,12,1)),NA()) -> 167649.97
A25: =Quarterly_Firm!A13 -> 2015Q4 | B25: =Quarterly_Firm!E13 -> -73814 | C25: =Quarterly_Firm!L13 -> 3623685.5 | D25: =Quarterly_Firm!Q13 -> -0.020369869 | E25: =IF(ROW()>2,IFERROR(B25-B24,""),"") -> -95313 | F25: =IF(ROW()>=5,_xlfn.STDEV.S(OFFSET(D25,-3,0,4,1)),NA()) -> 0.019530293 | G25: =IF(ROW()>=13,_xlfn.STDEV.S(OFFSET(D25,-11,0,12,1)),NA()) -> 0.037515678 | H25: =IF(ROW()>=5,_xlfn.STDEV.S(OFFSET(E25,-3,0,4,1)),NA()) -> 108279.35 | I25: =IF(ROW()>=13,_xlfn.STDEV.S(OFFSET(E25,-11,0,12,1)),NA()) -> 149105
... A63: =Quarterly_Firm!A51 -> 2025Q2 | B63: =Quarterly_Firm!E51 -> -21847 | C63: =Quarterly_Firm!L51 -> 2915395.5 | D63: =Quarterly_Firm!Q51 -> -0.007493666 | E63: =IF(ROW()>2,IFERROR(B63-B62,""),"") -> -10854 | F63: =IF(ROW()>=5,_xlfn.STDEV.S(OFFSET(D63,-3,0,4,1)),NA()) -> 0.014652739 | G63: =IF(ROW()>=13,_xlfn.STDEV.S(OFFSET(D63,-11,0,12,1)),NA()) -> 0.019576524 | H63: =IF(ROW()>=5,_xlfn.STDEV.S(OFFSET(E63,-3,0,4,1)),NA()) -> 55164.481 | I63: =IF(ROW()>=13,_xlfn.STDEV.S(OFFSET(E63,-11,0,12,1)),NA()) -> 61067.423

Sheet Constructed_Variables
A1: Quarter | B1: ROA | C1: NetIncome | D1: CFV_12Q_OCFtoAssets | E1: ERVol_12Q | F1: DER | G1: ln_TotalAssets | H1: CurrentRatio | I1: HedgingDummy | J1: ERVol_Q_Monthly_3M | K1: ERVol_Q_Monthly_12M
A2: =Quarterly_Firm!A2 -> 2013Q1 | B2: =Quarterly_Firm!M2 -> 0.00440569 | C2: =Quarterly_Firm!B2 -> 11130 | D2: =CFV_Calc!G14 -> 0.040526172 | E2: =FX_Calc!F14 -> 0.019212738 | F2: =Quarterly_Firm!N2 -> 0.89113539 | G2: =Quarterly_Firm!P2 -> 14.728038 | H2: =Quarterly_Firm!O2 -> 1.1244638 | I2: =Quarterly_Firm!J2 -> 0 | J2: =IFERROR(VLOOKUP(A2,Quarterly_FX!$A:$D,2,FALSE),NA()) -> 0.0010576188 | K2: =IFERROR(VLOOKUP(A2,Quarterly_FX!$A:$D,3,FALSE),NA()) -> 0.0050450092
A3: =Quarterly_Firm!A3 -> 2013Q2 | B3: =Quarterly_Firm!M3 -> -0.0024338622 | C3: =Quarterly_Firm!B3 -> -6281 | D3: =CFV_Calc!G15 -> 0.042834563 | E3: =FX_Calc!F15 -> 0.019514688 | F3: =Quarterly_Firm!N3 -> 1.0819482 | G3: =Quarterly_Firm!P3 -> 14.797864 | H3: =Quarterly_Firm!O3 -> 1.065631 | I3: =Quarterly_Firm!J3 -> 0 | J3: =IFERROR(VLOOKUP(A3,Quarterly_FX!$A:$D,2,FALSE),NA()) -> 0.0055437985 | K3: =IFERROR(VLOOKUP(A3,Quarterly_FX!$A:$D,3,FALSE),NA()) -> 0.0031361245
A4: =Quarterly_Firm!A4 -> 2013Q3 | B4: =Quarterly_Firm!M4 -> -0.018603758 | C4: =Quarterly_Firm!B4 -> -47658 | D4: =CFV_Calc!G16 -> 0.04175148 | E4: =FX_Calc!F16 -> 0.046194811 | F4: =Quarterly_Firm!N4 -> 0.99243826 | G4: =Quarterly_Firm!P4 -> 14.712719 | H4: =Quarterly_Firm!O4 -> 1.0203528 | I4: =Quarterly_Firm!J4 -> 1 | J4: =IFERROR(VLOOKUP(A4,Quarterly_FX!$A:$D,2,FALSE),NA()) -> 0.027955216 | K4: =IFERROR(VLOOKUP(A4,Quarterly_FX!$A:$D,3,FALSE),NA()) -> 0.022795677
A5: =Quarterly_Firm!A5 -> 2013Q4 | B5: =Quarterly_Firm!M5 -> -0.0087300251 | C5: =Quarterly_Firm!B5 -> -21109 | D5: =CFV_Calc!G17 -> 0.044327421 | E5: =FX_Calc!F17 -> 0.046590776 | F5: =Quarterly_Firm!N5 -> 0.96923338 | G5: =Quarterly_Firm!P5 -> 14.683958 | H5: =Quarterly_Firm!O5 -> 0.96228255 | I5: =Quarterly_Firm!J5 -> 1 | J5: =IFERROR(VLOOKUP(A5,Quarterly_FX!$A:$D,2,FALSE),NA()) -> 0.020331594 | K5: =IFERROR(VLOOKUP(A5,Quarterly_FX!$A:$D,3,FALSE),NA()) -> 0.023472673
A6: =Quarterly_Firm!A6 -> 2014Q1 | B6: =Quarterly_Firm!M6 -> -0.031191003 | C6: =Quarterly_Firm!B6 -> -73521 | D6: =CFV_Calc!G18 -> 0.044464499 | E6: =FX_Calc!F18 -> 0.051097814 | F6: =Quarterly_Firm!N6 -> 1.0668384 | G6: =Quarterly_Firm!P6 -> 14.661824 | H6: =Quarterly_Firm!O6 -> 0.96126156 | I6: =Quarterly_Firm!J6 -> 1 | J6: =IFERROR(VLOOKUP(A6,Quarterly_FX!$A:$D,2,FALSE),NA()) -> 0.025398804 | K6: =IFERROR(VLOOKUP(A6,Quarterly_FX!$A:$D,3,FALSE),NA()) -> 0.030833377
A7: =Quarterly_Firm!A7 -> 2014Q2 | B7: =Quarterly_Firm!M7 -> -0.0072903911 | C7: =Quarterly_Firm!B7 -> -17863 | D7: =CFV_Calc!G19 -> 0.046837925 | E7: =FX_Calc!F19 -> 0.050293683 | F7: =Quarterly_Firm!N7 -> 1.26282 | G7: =Quarterly_Firm!P7 -> 14.759178 | H7: =Quarterly_Firm!O7 -> 0.90706058 | I7: =Quarterly_Firm!J7 -> 1 | J7: =IFERROR(VLOOKUP(A7,Quarterly_FX!$A:$D,2,FALSE),NA()) -> 0.015866794 | K7: =IFERROR(VLOOKUP(A7,Quarterly_FX!$A:$D,3,FALSE),NA()) -> 0.031150249
A8: =Quarterly_Firm!A8 -> 2014Q3 | B8: =Quarterly_Firm!M8 -> -0.0090562269 | C8: =Quarterly_Firm!B8 -> -23413 | D8: =CFV_Calc!G20 -> 0.044806448 | E8: =FX_Calc!F20 -> 0.050339212 | F8: =Quarterly_Firm!N8 -> 1.4286046 | G8: =Quarterly_Firm!P8 -> 14.771483 | H8: =Quarterly_Firm!O8 -> 0.90545296 | I8: =Quarterly_Firm!J8 -> 1 | J8: =IFERROR(VLOOKUP(A8,Quarterly_FX!$A:$D,2,FALSE),NA()) -> 0.017916166 | K8: =IFERROR(VLOOKUP(A8,Quarterly_FX!$A:$D,3,FALSE),NA()) -> 0.02350869
A9: =Quarterly_Firm!A9 -> 2014Q4 | B9: =Quarterly_Firm!M9 -> -0.017484008 | C9: =Quarterly_Firm!B9 -> -45507 | D9: =CFV_Calc!G21 -> 0.043397692 | E9: =FX_Calc!F21 -> 0.050399773 | F9: =Quarterly_Firm!N9 -> 1.5201601 | G9: =Quarterly_Firm!P9 -> 14.772696 | H9: =Quarterly_Firm!O9 -> 0.74904602 | I9: =Quarterly_Firm!J9 -> 1 | J9: =IFERROR(VLOOKUP(A9,Quarterly_FX!$A:$D,2,FALSE),NA()) -> 0.012220506 | K9: =IFERROR(VLOOKUP(A9,Quarterly_FX!$A:$D,3,FALSE),NA()) -> 0.021151016
A10: =Quarterly_Firm!A10 -> 2015Q1 | B10: =Quarterly_Firm!M10 -> -0.017653485 | C10: =Quarterly_Firm!B10 -> -46566 | D10: =CFV_Calc!G22 -> 0.043325064 | E10: =FX_Calc!F22 -> 0.050635928 | F10: =Quarterly_Firm!N10 -> 1.8273073 | G10: =Quarterly_Firm!P10 -> 14.798039 | H10: =Quarterly_Firm!O10 -> 0.73238529 | I10: =Quarterly_Firm!J10 -> 1 | J10: =IFERROR(VLOOKUP(A10,Quarterly_FX!$A:$D,2,FALSE),NA()) -> 0.0071444446 | K10: =IFERROR(VLOOKUP(A10,Quarterly_FX!$A:$D,3,FALSE),NA()) -> 0.013647753
A11: =Quarterly_Firm!A11 -> 2015Q2 | B11: =Quarterly_Firm!M11 -> -0.04049229 | C11: =Quarterly_Firm!B11 -> -105213 | D11: =CFV_Calc!G23 -> 0.043418373 | E11: =FX_Calc!F23 -> 0.050720071 | F11: =Quarterly_Firm!N11 -> 2.0375562 | G11: =Quarterly_Firm!P11 -> 14.741946 | H11: =Quarterly_Firm!O11 -> 0.59184853 | I11: =Quarterly_Firm!J11 -> 1 | J11: =IFERROR(VLOOKUP(A11,Quarterly_FX!$A:$D,2,FALSE),NA()) -> 0.013347355 | K11: =IFERROR(VLOOKUP(A11,Quarterly_FX!$A:$D,3,FALSE),NA()) -> 0.013234298
A12: =Quarterly_Firm!A12 -> 2015Q3 | B12: =Quarterly_Firm!M12 -> 0.34944993 | C12: =Quarterly_Firm!B12 -> 1060706 | D12: =CFV_Calc!G24 -> 0.040916634 | E12: =FX_Calc!F24 -> 0.053789384 | F12: =Quarterly_Firm!N12 -> 0.79401926 | G12: =Quarterly_Firm!P12 -> 15.081113 | H12: =Quarterly_Firm!O12 -> 0.59302963 | I12: =Quarterly_Firm!J12 -> 1 | J12: =IFERROR(VLOOKUP(A12,Quarterly_FX!$A:$D,2,FALSE),NA()) -> 0.021039599 | K12: =IFERROR(VLOOKUP(A12,Quarterly_FX!$A:$D,3,FALSE),NA()) -> 0.014310775
A13: =Quarterly_Firm!A13 -> 2015Q4 | B13: =Quarterly_Firm!M13 -> -0.0018644002 | C13: =Quarterly_Firm!B13 -> -6756 | D13: =CFV_Calc!G25 -> 0.037515678 | E13: =FX_Calc!F25 -> 0.060241208 | F13: =Quarterly_Firm!N13 -> 0.91049362 | G13: =Quarterly_Firm!P13 -> 15.124423 | H13: =Quarterly_Firm!O13 -> 0.60893575 | I13: =Quarterly_Firm!J13 -> 1 | J13: =IFERROR(VLOOKUP(A13,Quarterly_FX!$A:$D,2,FALSE),NA()) -> 0.028549491 | K13: =IFERROR(VLOOKUP(A13,Quarterly_FX!$A:$D,3,FALSE),NA()) -> 0.0224817
... A51: =Quarterly_Firm!A51 -> 2025Q2 | B51: =Quarterly_Firm!M51 -> -0.014884087 | C51: =Quarterly_Firm!B51 -> -43393 | D51: =CFV_Calc!G63 -> 0.019576524 | E51: =FX_Calc!F63 -> 0.039631306 | F51: =Quarterly_Firm!N51 -> 5.2657572 | G51: =Quarterly_Firm!P51 -> 14.884465 | H51: =Quarterly_Firm!O51 -> 0.27361225 | I51: =Quarterly_Firm!J51 -> 0 | J51: =IFERROR(VLOOKUP(A51,Quarterly_FX!$A:$D,2,FALSE),NA()) -> 0.019437256 | K51: =IFERROR(VLOOKUP(A51,Quarterly_FX!$A:$D,3,FALSE),NA()) -> 0.017665206

Sheet Notes
A1: INSTRUCTIONS:
A2: 1) Enter Krakatau Steel quarterly data in 'Quarterly_Firm' (A–K). Replace the example numbers.
A3: 2) Columns L–Q compute derived variables automatically.
A4: 3) 'FX_Calc' computes ln(E), quarterly log returns r_t, and rolling volatility over 4 and 12 quarters using STDEV.S and OFFSET.
A5: 4) 'CFV_Calc' computes cash-flow volatility as rolling SD of OCF/AvgAssets and of ΔOCF over 4 and 12 quarters.
A6: 5) 'Constructed_Variables' gathers variables for regression.
A7: FORMULA EXAMPLES:
A8: • ln(E) = LN(B2) where B is IDRUSD_QuarterEnd.
A9: • Quarterly log return r_t = C3 - C2 where C is ln(E).
A10: • 4Q FX volatility (row 5): =STDEV.S(OFFSET(D5,-3,0,4,1)) -> uses D2:D5.
A11: • 12Q FX volatility (row 13): =STDEV.S(OFFSET(D13,-11,0,12,1)) -> uses D2:D13.
A12: • ΔOCF = B3 - B2 in 'CFV_Calc'.
... A29: 2020 and 2021 was restated on 2022

Sheet Charts

Sheet Daily_FX
A1: Date | B1: IDRUSD_Spot (paste JISDOR/daily) | C1: Month (yyyy-mm) | D1: Quarter (YYYYQ#)
A2: 40909 | B2: 9068 | C2: 2012-01 | D2: 2012Q1
A3: 40910 | B3: 9125 | C3: 2012-01 | D3: 2012Q1
A4: 40911 | B4: 9160 | C4: 2012-01 | D4: 2012Q1
A5: 40912 | B5: 9180 | C5: 2012-01 | D5: 2012Q1
A6: 40913 | B6: 9163 | C6: 2012-01 | D6: 2012Q1
A7: 40914 | B7: 9160 | C7: 2012-01 | D7: 2012Q1
A8: 40915 | B8: 9160 | C8: 2012-01 | D8: 2012Q1
A9: 40916 | B9: 9160 | C9: 2012-01 | D9: 2012Q1
A10: 40917 | B10: 9188 | C10: 2012-01 | D10: 2012Q1
A11: 40918 | B11: 9190 | C11: 2012-01 | D11: 2012Q1
A12: 40919 | B12: 9200 | C12: 2012-01 | D12: 2012Q1
A13: 40920 | B13: 9210 | C13: 2012-01 | D13: 2012Q1
... A367: 41274 | B367: 9670 | C367: 2012-12 | D367: 2012Q4
A368: 2013-01-01 | B368: 9670 | C368: 2013-01 | D368: 2013Q1
A369: 2013-01-02 | B369: 9685 | C369: 2013-01 | D369: 2013Q1
A370: 2013-01-03 | B370: 9670 | C370: 2013-01 | D370: 2013Q1
A371: 2013-01-04 | B371: 9675 | C371: 2013-01 | D371: 2013Q1
A372: 2013-01-05 | B372: 9675 | C372: 2013-01 | D372: 2013Q1
A373: 2013-01-06 | B373: 9675 | C373: 2013-01 | D373: 2013Q1
A374: 2013-01-07 | B374: 9738 | C374: 2013-01 | D374: 2013Q1
A375: 2013-01-08 | B375: 9740 | C375: 2013-01 | D375: 2013Q1
A376: 2013-01-09 | B376: 9740 | C376: 2013-01 | D376: 2013Q1
A377: 2013-01-10 | B377: 9715 | C377: 2013-01 | D377: 2013Q1
A378: 2013-01-11 | B378: 9660 | C378: 2013-01 | D378: 2013Q1
A379: 2013-01-12 | B379: 9660 | C379: 2013-01 | D379: 2013Q1
... A5023: 2025-09-30 | B5023: 16680 | C5023: 2025-09 | D5023: 2025Q3

Sheet Monthly_FX
A1: Month (YYYY-MM) | B1: IDRUSD_MonthAvg (from Daily_FX) | C1: lnE_m | D1: r_m (Monthly log return) | E1: Quarter | F1: ERVol_Q_fromMonthly_3M | G1: ERVol_Q_fromMonthly_12M
A2: 2012-01 | B2: =AVERAGE(Daily_FX!B2:B32) -> 9092.4194 | C2: =IFERROR(LN(B2),"") -> 9.1151963 | E2: =LEFT(A2,4)&"Q"&ROUNDUP(VALUE(RIGHT(A2,2))/3,0) -> 2012Q1
A3: 2012-02 | B3: =AVERAGE(Daily_FX!B33:B61) -> 9014.2414 | C3: =IFERROR(LN(B3),"") -> 9.106561 | D3: =IFERROR(C3-C2,"") -> -0.0086353262 | E3: =LEFT(A3,4)&"Q"&ROUNDUP(VALUE(RIGHT(A3,2))/3,0) -> 2012Q1
A4: 2012-03 | B4: =AVERAGE(Daily_FX!B62:B92) -> 9161.5806 | C4: =IFERROR(LN(B4),"") -> 9.122774 | D4: =IFERROR(C4-C3,"") -> 0.016213021 | E4: =LEFT(A4,4)&"Q"&ROUNDUP(VALUE(RIGHT(A4,2))/3,0) -> 2012Q1
A5: 2012-04 | B5: =AVERAGE(Daily_FX!B93:B122) -> 9175.4333 | C5: =IFERROR(LN(B5),"") -> 9.1242849 | D5: =IFERROR(C5-C4,"") -> 0.0015108993 | E5: =LEFT(A5,4)&"Q"&ROUNDUP(VALUE(RIGHT(A5,2))/3,0) -> 2012Q2
A6: 2012-05 | B6: =AVERAGE(Daily_FX!B123:B153) -> 9278.4194 | C6: =IFERROR(LN(B6),"") -> 9.1354465 | D6: =IFERROR(C6-C5,"") -> 0.011161582 | E6: =LEFT(A6,4)&"Q"&ROUNDUP(VALUE(RIGHT(A6,2))/3,0) -> 2012Q2
A7: 2012-06 | B7: =AVERAGE(Daily_FX!B154:B183) -> 9445.6 | C7: =IFERROR(LN(B7),"") -> 9.1533043 | D7: =IFERROR(C7-C6,"") -> 0.01785782 | E7: =LEFT(A7,4)&"Q"&ROUNDUP(VALUE(RIGHT(A7,2))/3,0) -> 2012Q2
A8: 2012-07 | B8: =AVERAGE(Daily_FX!B184:B214) -> 9458.6129 | C8: =IFERROR(LN(B8),"") -> 9.154681 | D8: =IFERROR(C8-C7,"") -> 0.0013767201 | E8: =LEFT(A8,4)&"Q"&ROUNDUP(VALUE(RIGHT(A8,2))/3,0) -> 2012Q3
A9: 2012-08 | B9: =AVERAGE(Daily_FX!B215:B245) -> 9497.3226 | C9: =IFERROR(LN(B9),"") -> 9.1587652 | D9: =IFERROR(C9-C8,"") -> 0.0040841805 | E9: =LEFT(A9,4)&"Q"&ROUNDUP(VALUE(RIGHT(A9,2))/3,0) -> 2012Q3
A10: 2012-09 | B10: =AVERAGE(Daily_FX!B246:B275) -> 9569.0333 | C10: =IFERROR(LN(B10),"") -> 9.1662875 | D10: =IFERROR(C10-C9,"") -> 0.007522265 | E10: =LEFT(A10,4)&"Q"&ROUNDUP(VALUE(RIGHT(A10,2))/3,0) -> 2012Q3
A11: 2012-10 | B11: =AVERAGE(Daily_FX!B276:B306) -> 9598.3548 | C11: =IFERROR(LN(B11),"") -> 9.169347 | D11: =IFERROR(C11-C10,"") -> 0.0030595226 | E11: =LEFT(A11,4)&"Q"&ROUNDUP(VALUE(RIGHT(A11,2))/3,0) -> 2012Q4
A12: 2012-11 | B12: =AVERAGE(Daily_FX!B307:B336) -> 9629.6333 | C12: =IFERROR(LN(B12),"") -> 9.1726004 | D12: =IFERROR(C12-C11,"") -> 0.0032534368 | E12: =LEFT(A12,4)&"Q"&ROUNDUP(VALUE(RIGHT(A12,2))/3,0) -> 2012Q4
A13: 2012-12 | B13: =AVERAGE(Daily_FX!B337:B367) -> 9649.4839 | C13: =IFERROR(LN(B13),"") -> 9.1746597 | D13: =IFERROR(C13-C12,"") -> 0.0020592794 | E13: =LEFT(A13,4)&"Q"&ROUNDUP(VALUE(RIGHT(A13,2))/3,0) -> 2012Q4
A14: 2013-01 | B14: =AVERAGE(Daily_FX!B368:B398) -> 9679.5161 | C14: =IFERROR(LN(B14),"") -> 9.1777672 | D14: =IFERROR(C14-C13,"") -> 0.0031074843 | E14: =LEFT(A14,4)&"Q"&ROUNDUP(VALUE(RIGHT(A14,2))/3,0) -> 2013Q1 | F14: =IF(ROW()>4,_xlfn.STDEV.S(OFFSET(D14,-2,0,3,1)),NA()) -> 0.00065141481 | G14: =IF(ROW()>13,_xlfn.STDEV.S(OFFSET(D14,-11,0,12,1)),NA()) -> 0.0071728004
A15: 2013-02 | B15: =AVERAGE(Daily_FX!B399:B426) -> 9689.1786 | C15: =IFERROR(LN(B15),"") -> 9.1787649 | D15: =IFERROR(C15-C14,"") -> 0.00099773819 | E15: =LEFT(A15,4)&"Q"&ROUNDUP(VALUE(RIGHT(A15,2))/3,0) -> 2013Q1 | F15: =IF(ROW()>4,_xlfn.STDEV.S(OFFSET(D15,-2,0,3,1)),NA()) -> 0.0010548801 | G15: =IF(ROW()>13,_xlfn.STDEV.S(OFFSET(D15,-11,0,12,1)),NA()) -> 0.0059097387
A16: 2013-03 | B16: =AVERAGE(Daily_FX!B427:B457) -> 9707.8065 | C16: =IFERROR(LN(B16),"") -> 9.1806856 | D16: =IFERROR(C16-C15,"") -> 0.0019206991 | E16: =LEFT(A16,4)&"Q"&ROUNDUP(VALUE(RIGHT(A16,2))/3,0) -> 2013Q1 | F16: =IF(ROW()>4,_xlfn.STDEV.S(OFFSET(D16,-2,0,3,1)),NA()) -> 0.0010576188 | G16: =IF(ROW()>13,_xlfn.STDEV.S(OFFSET(D16,-11,0,12,1)),NA()) -> 0.0050450092
A17: 2013-04 | B17: =AVERAGE(Daily_FX!B458:B487) -> 9723.8333 | C17: =IFERROR(LN(B17),"") -> 9.1823352 | D17: =IFERROR(C17-C16,"") -> 0.0016495659 | E17: =LEFT(A17,4)&"Q"&ROUNDUP(VALUE(RIGHT(A17,2))/3,0) -> 2013Q2 | F17: =IF(ROW()>4,_xlfn.STDEV.S(OFFSET(D17,-2,0,3,1)),NA()) -> 0.00047438547 | G17: =IF(ROW()>13,_xlfn.STDEV.S(OFFSET(D17,-11,0,12,1)),NA()) -> 0.0050368781
A18: 2013-05 | B18: =AVERAGE(Daily_FX!B488:B518) -> 9758.0645 | C18: =IFERROR(LN(B18),"") -> 9.1858494 | D18: =IFERROR(C18-C17,"") -> 0.0035141564 | E18: =LEFT(A18,4)&"Q"&ROUNDUP(VALUE(RIGHT(A18,2))/3,0) -> 2013Q2 | F18: =IF(ROW()>4,_xlfn.STDEV.S(OFFSET(D18,-2,0,3,1)),NA()) -> 0.0010074156 | G18: =IF(ROW()>13,_xlfn.STDEV.S(OFFSET(D18,-11,0,12,1)),NA()) -> 0.0046314691
A19: 2013-06 | B19: =AVERAGE(Daily_FX!B519:B548) -> 9876.3333 | C19: =IFERROR(LN(B19),"") -> 9.1978966 | D19: =IFERROR(C19-C18,"") -> 0.01204725 | E19: =LEFT(A19,4)&"Q"&ROUNDUP(VALUE(RIGHT(A19,2))/3,0) -> 2013Q2 | F19: =IF(ROW()>4,_xlfn.STDEV.S(OFFSET(D19,-2,0,3,1)),NA()) -> 0.0055437985 | G19: =IF(ROW()>13,_xlfn.STDEV.S(OFFSET(D19,-11,0,12,1)),NA()) -> 0.0031361245
A20: 2013-07 | B20: =AVERAGE(Daily_FX!B549:B579) -> 10071.226 | C20: =IFERROR(LN(B20),"") -> 9.2174377 | D20: =IFERROR(C20-C19,"") -> 0.019541105 | E20: =LEFT(A20,4)&"Q"&ROUNDUP(VALUE(RIGHT(A20,2))/3,0) -> 2013Q3 | F20: =IF(ROW()>4,_xlfn.STDEV.S(OFFSET(D20,-2,0,3,1)),NA()) -> 0.008019088 | G20: =IF(ROW()>13,_xlfn.STDEV.S(OFFSET(D20,-11,0,12,1)),NA()) -> 0.0054410348
A21: 2013-08 | B21: =AVERAGE(Daily_FX!B580:B610) -> 10516.548 | C21: =IFERROR(LN(B21),"") -> 9.2607053 | D21: =IFERROR(C21-C20,"") -> 0.043267626 | E21: =LEFT(A21,4)&"Q"&ROUNDUP(VALUE(RIGHT(A21,2))/3,0) -> 2013Q3 | F21: =IF(ROW()>4,_xlfn.STDEV.S(OFFSET(D21,-2,0,3,1)),NA()) -> 0.016298351 | G21: =IF(ROW()>13,_xlfn.STDEV.S(OFFSET(D21,-11,0,12,1)),NA()) -> 0.012222475
A22: 2013-09 | B22: =AVERAGE(Daily_FX!B611:B640) -> 11338.433 | C22: =IFERROR(LN(B22),"") -> 9.3359534 | D22: =IFERROR(C22-C21,"") -> 0.075248081 | E22: =LEFT(A22,4)&"Q"&ROUNDUP(VALUE(RIGHT(A22,2))/3,0) -> 2013Q3 | F22: =IF(ROW()>4,_xlfn.STDEV.S(OFFSET(D22,-2,0,3,1)),NA()) -> 0.027955216 | G22: =IF(ROW()>13,_xlfn.STDEV.S(OFFSET(D22,-11,0,12,1)),NA()) -> 0.022795677
A23: 2013-10 | B23: =AVERAGE(Daily_FX!B641:B671) -> 11374.742 | C23: =IFERROR(LN(B23),"") -> 9.3391506 | D23: =IFERROR(C23-C22,"") -> 0.0031971429 | E23: =LEFT(A23,4)&"Q"&ROUNDUP(VALUE(RIGHT(A23,2))/3,0) -> 2013Q4 | F23: =IF(ROW()>4,_xlfn.STDEV.S(OFFSET(D23,-2,0,3,1)),NA()) -> 0.036101087 | G23: =IF(ROW()>13,_xlfn.STDEV.S(OFFSET(D23,-11,0,12,1)),NA()) -> 0.022789631
A24: 2013-11 | B24: =AVERAGE(Daily_FX!B672:B701) -> 11589.267 | C24: =IFERROR(LN(B24),"") -> 9.3578347 | D24: =IFERROR(C24-C23,"") -> 0.018684105 | E24: =LEFT(A24,4)&"Q"&ROUNDUP(VALUE(RIGHT(A24,2))/3,0) -> 2013Q4 | F24: =IF(ROW()>4,_xlfn.STDEV.S(OFFSET(D24,-2,0,3,1)),NA()) -> 0.037926831 | G24: =IF(ROW()>13,_xlfn.STDEV.S(OFFSET(D24,-11,0,12,1)),NA()) -> 0.022552991
A25: 2013-12 | B25: =AVERAGE(Daily_FX!B702:B732) -> 12104.548 | C25: =IFERROR(LN(B25),"") -> 9.4013366 | D25: =IFERROR(C25-C24,"") -> 0.043501899 | E25: =LEFT(A25,4)&"Q"&ROUNDUP(VALUE(RIGHT(A25,2))/3,0) -> 2013Q4 | F25: =IF(ROW()>4,_xlfn.STDEV.S(OFFSET(D25,-2,0,3,1)),NA()) -> 0.020331594 | G25: =IF(ROW()>13,_xlfn.STDEV.S(OFFSET(D25,-11,0,12,1)),NA()) -> 0.023472673
A26: 2014-01 | B26: =AVERAGE(Daily_FX!B733:B763) -> 12177.71 | C26: =IFERROR(LN(B26),"") -> 9.4073625 | D26: =IFERROR(C26-C25,"") -> 0.0060259232 | E26: =LEFT(A26,4)&"Q"&ROUNDUP(VALUE(RIGHT(A26,2))/3,0) -> 2014Q1 | F26: =IF(ROW()>4,_xlfn.STDEV.S(OFFSET(D26,-2,0,3,1)),NA()) -> 0.019063933 | G26: =IF(ROW()>13,_xlfn.STDEV.S(OFFSET(D26,-11,0,12,1)),NA()) -> 0.023308833
A27: 2014-02 | B27: =AVERAGE(Daily_FX!B764:B791) -> 11959.357 | C27: =IFERROR(LN(B27),"") -> 9.3892693 | D27: =IFERROR(C27-C26,"") -> -0.018093208 | E27: =LEFT(A27,4)&"Q"&ROUNDUP(VALUE(RIGHT(A27,2))/3,0) -> 2014Q1 | F27: =IF(ROW()>4,_xlfn.STDEV.S(OFFSET(D27,-2,0,3,1)),NA()) -> 0.031037984 | G27: =IF(ROW()>13,_xlfn.STDEV.S(OFFSET(D27,-11,0,12,1)),NA()) -> 0.025231378
A28: 2014-03 | B28: =AVERAGE(Daily_FX!B792:B822) -> 11435.968 | C28: =IFERROR(LN(B28),"") -> 9.3445187 | D28: =IFERROR(C28-C27,"") -> -0.044750543 | E28: =LEFT(A28,4)&"Q"&ROUNDUP(VALUE(RIGHT(A28,2))/3,0) -> 2014Q1 | F28: =IF(ROW()>4,_xlfn.STDEV.S(OFFSET(D28,-2,0,3,1)),NA()) -> 0.025398804 | G28: =IF(ROW()>13,_xlfn.STDEV.S(OFFSET(D28,-11,0,12,1)),NA()) -> 0.030833377
A29: 2014-04 | B29: =AVERAGE(Daily_FX!B823:B852) -> 11433.333 | C29: =IFERROR(LN(B29),"") -> 9.3442883 | D29: =IFERROR(C29-C28,"") -> -0.00023038821 | E29: =LEFT(A29,4)&"Q"&ROUNDUP(VALUE(RIGHT(A29,2))/3,0) -> 2014Q2 | F29: =IF(ROW()>4,_xlfn.STDEV.S(OFFSET(D29,-2,0,3,1)),NA()) -> 0.022404382 | G29: =IF(ROW()>13,_xlfn.STDEV.S(OFFSET(D29,-11,0,12,1)),NA()) -> 0.030904603
A30: 2014-05 | B30: =AVERAGE(Daily_FX!B853:B883) -> 11532.032 | C30: =IFERROR(LN(B30),"") -> 9.3528839 | D30: =IFERROR(C30-C29,"") -> 0.0085955115 | E30: =LEFT(A30,4)&"Q"&ROUNDUP(VALUE(RIGHT(A30,2))/3,0) -> 2014Q2 | F30: =IF(ROW()>4,_xlfn.STDEV.S(OFFSET(D30,-2,0,3,1)),NA()) -> 0.02859412 | G30: =IF(ROW()>13,_xlfn.STDEV.S(OFFSET(D30,-11,0,12,1)),NA()) -> 0.030789998
A31: 2014-06 | B31: =AVERAGE(Daily_FX!B884:B913) -> 11890.133 | C31: =IFERROR(LN(B31),"") -> 9.3834642 | D31: =IFERROR(C31-C30,"") -> 0.030580348 | E31: =LEFT(A31,4)&"Q"&ROUNDUP(VALUE(RIGHT(A31,2))/3,0) -> 2014Q2 | F31: =IF(ROW()>4,_xlfn.STDEV.S(OFFSET(D31,-2,0,3,1)),NA()) -> 0.015866794 | G31: =IF(ROW()>13,_xlfn.STDEV.S(OFFSET(D31,-11,0,12,1)),NA()) -> 0.031150249
A32: 2014-07 | B32: =AVERAGE(Daily_FX!B914:B944) -> 11666.581 | C32: =IFERROR(LN(B32),"") -> 9.3644837 | D32: =IFERROR(C32-C31,"") -> -0.018980525 | E32: =LEFT(A32,4)&"Q"&ROUNDUP(VALUE(RIGHT(A32,2))/3,0) -> 2014Q3 | F32: =IF(ROW()>4,_xlfn.STDEV.S(OFFSET(D32,-2,0,3,1)),NA()) -> 0.024832945 | G32: =IF(ROW()>13,_xlfn.STDEV.S(OFFSET(D32,-11,0,12,1)),NA()) -> 0.032641104
A33: 2014-08 | B33: =AVERAGE(Daily_FX!B945:B975) -> 11697.226 | C33: =IFERROR(LN(B33),"") -> 9.367107 | D33: =IFERROR(C33-C32,"") -> 0.0026233036 | E33: =LEFT(A33,4)&"Q"&ROUNDUP(VALUE(RIGHT(A33,2))/3,0) -> 2014Q3 | F33: =IF(ROW()>4,_xlfn.STDEV.S(OFFSET(D33,-2,0,3,1)),NA()) -> 0.024848212 | G33: =IF(ROW()>13,_xlfn.STDEV.S(OFFSET(D33,-11,0,12,1)),NA()) -> 0.031207643
A34: 2014-09 | B34: =AVERAGE(Daily_FX!B976:B1005) -> 11892.767 | C34: =IFERROR(LN(B34),"") -> 9.3836857 | D34: =IFERROR(C34-C33,"") -> 0.016578669 | E34: =LEFT(A34,4)&"Q"&ROUNDUP(VALUE(RIGHT(A34,2))/3,0) -> 2014Q3 | F34: =IF(ROW()>4,_xlfn.STDEV.S(OFFSET(D34,-2,0,3,1)),NA()) -> 0.017916166 | G34: =IF(ROW()>13,_xlfn.STDEV.S(OFFSET(D34,-11,0,12,1)),NA()) -> 0.02350869
A35: 2014-10 | B35: =AVERAGE(Daily_FX!B1006:B1036) -> 12148.645 | C35: =IFERROR(LN(B35),"") -> 9.4049729 | D35: =IFERROR(C35-C34,"") -> 0.021287282 | E35: =LEFT(A35,4)&"Q"&ROUNDUP(VALUE(RIGHT(A35,2))/3,0) -> 2014Q4 | F35: =IF(ROW()>4,_xlfn.STDEV.S(OFFSET(D35,-2,0,3,1)),NA()) -> 0.0097062467 | G35: =IF(ROW()>13,_xlfn.STDEV.S(OFFSET(D35,-11,0,12,1)),NA()) -> 0.024028365
A36: 2014-11 | B36: =AVERAGE(Daily_FX!B1037:B1066) -> 12158.467 | C36: =IFERROR(LN(B36),"") -> 9.4057811 | D36: =IFERROR(C36-C35,"") -> 0.00080811789 | E36: =LEFT(A36,4)&"Q"&ROUNDUP(VALUE(RIGHT(A36,2))/3,0) -> 2014Q4 | F36: =IF(ROW()>4,_xlfn.STDEV.S(OFFSET(D36,-2,0,3,1)),NA()) -> 0.010725961 | G36: =IF(ROW()>13,_xlfn.STDEV.S(OFFSET(D36,-11,0,12,1)),NA()) -> 0.023687396
A37: 2014-12 | B37: =AVERAGE(Daily_FX!B1067:B1097) -> 12436.387 | C37: =IFERROR(LN(B37),"") -> 9.4283819 | D37: =IFERROR(C37-C36,"") -> 0.022600847 | E37: =LEFT(A37,4)&"Q"&ROUNDUP(VALUE(RIGHT(A37,2))/3,0) -> 2014Q4 | F37: =IF(ROW()>4,_xlfn.STDEV.S(OFFSET(D37,-2,0,3,1)),NA()) -> 0.012220506 | G37: =IF(ROW()>13,_xlfn.STDEV.S(OFFSET(D37,-11,0,12,1)),NA()) -> 0.021151016
A38: 2015-01 | B38: =AVERAGE(Daily_FX!B1098:B1128) -> 12565.419 | C38: =IFERROR(LN(B38),"") -> 9.4387038 | D38: =IFERROR(C38-C37,"") -> 0.010321926 | E38: =LEFT(A38,4)&"Q"&ROUNDUP(VALUE(RIGHT(A38,2))/3,0) -> 2015Q1 | F38: =IF(ROW()>4,_xlfn.STDEV.S(OFFSET(D38,-2,0,3,1)),NA()) -> 0.010925562 | G38: =IF(ROW()>13,_xlfn.STDEV.S(OFFSET(D38,-11,0,12,1)),NA()) -> 0.02125676
A39: 2015-02 | B39: =AVERAGE(Daily_FX!B1129:B1156) -> 12750.036 | C39: =IFERROR(LN(B39),"") -> 9.4532894 | D39: =IFERROR(C39-C38,"") -> 0.014585527 | E39: =LEFT(A39,4)&"Q"&ROUNDUP(VALUE(RIGHT(A39,2))/3,0) -> 2015Q1 | F39: =IF(ROW()>4,_xlfn.STDEV.S(OFFSET(D39,-2,0,3,1)),NA()) -> 0.0062342538 | G39: =IF(ROW()>13,_xlfn.STDEV.S(OFFSET(D39,-11,0,12,1)),NA()) -> 0.02044067
A40: 2015-03 | B40: =AVERAGE(Daily_FX!B1157:B1187) -> 13063.194 | C40: =IFERROR(LN(B40),"") -> 9.4775539 | D40: =IFERROR(C40-C39,"") -> 0.02426455 | E40: =LEFT(A40,4)&"Q"&ROUNDUP(VALUE(RIGHT(A40,2))/3,0) -> 2015Q1 | F40: =IF(ROW()>4,_xlfn.STDEV.S(OFFSET(D40,-2,0,3,1)),NA()) -> 0.0071444446 | G40: =IF(ROW()>13,_xlfn.STDEV.S(OFFSET(D40,-11,0,12,1)),NA()) -> 0.013647753
...

Sheet Quarterly_FX
A1: Quarter | B1: ERVol_Q_fromMonthly_3M | C1: ERVol_Q_fromMonthly_12M | D1: IDRUSD (last month in Q)
A2: 2013Q1 | B2: =IFERROR(LOOKUP(2,1/(Monthly_FX!$E:$E=A2),Monthly_FX!$F:$F),NA()) -> 0.0010576188 | C2: =IFERROR(LOOKUP(2,1/(Monthly_FX!$E:$E=A2),Monthly_FX!$G:$G),NA()) -> 0.0050450092 | D2: =IFERROR(LOOKUP(2,1/(Monthly_FX!$E:$E=A2),Monthly_FX!$B:$B),NA()) -> 9707.8065
A3: 2013Q2 | B3: =IFERROR(LOOKUP(2,1/(Monthly_FX!$E:$E=A3),Monthly_FX!$F:$F),NA()) -> 0.0055437985 | C3: =IFERROR(LOOKUP(2,1/(Monthly_FX!$E:$E=A3),Monthly_FX!$G:$G),NA()) -> 0.0031361245 | D3: =IFERROR(LOOKUP(2,1/(Monthly_FX!$E:$E=A3),Monthly_FX!$B:$B),NA()) -> 9876.3333
A4: 2013Q3 | B4: =IFERROR(LOOKUP(2,1/(Monthly_FX!$E:$E=A4),Monthly_FX!$F:$F),NA()) -> 0.027955216 | C4: =IFERROR(LOOKUP(2,1/(Monthly_FX!$E:$E=A4),Monthly_FX!$G:$G),NA()) -> 0.022795677 | D4: =IFERROR(LOOKUP(2,1/(Monthly_FX!$E:$E=A4),Monthly_FX!$B:$B),NA()) -> 11338.433
A5: 2013Q4 | B5: =IFERROR(LOOKUP(2,1/(Monthly_FX!$E:$E=A5),Monthly_FX!$F:$F),NA()) -> 0.020331594 | C5: =IFERROR(LOOKUP(2,1/(Monthly_FX!$E:$E=A5),Monthly_FX!$G:$G),NA()) -> 0.023472673 | D5: =IFERROR(LOOKUP(2,1/(Monthly_FX!$E:$E=A5),Monthly_FX!$B:$B),NA()) -> 12104.548
A6: 2014Q1 | B6: =IFERROR(LOOKUP(2,1/(Monthly_FX!$E:$E=A6),Monthly_FX!$F:$F),NA()) -> 0.025398804 | C6: =IFERROR(LOOKUP(2,1/(Monthly_FX!$E:$E=A6),Monthly_FX!$G:$G),NA()) -> 0.030833377 | D6: =IFERROR(LOOKUP(2,1/(Monthly_FX!$E:$E=A6),Monthly_FX!$B:$B),NA()) -> 11435.968
A7: 2014Q2 | B7: =IFERROR(LOOKUP(2,1/(Monthly_FX!$E:$E=A7),Monthly_FX!$F:$F),NA()) -> 0.015866794 | C7: =IFERROR(LOOKUP(2,1/(Monthly_FX!$E:$E=A7),Monthly_FX!$G:$G),NA()) -> 0.031150249 | D7: =IFERROR(LOOKUP(2,1/(Monthly_FX!$E:$E=A7),Monthly_FX!$B:$B),NA()) -> 11890.133
A8: 2014Q3 | B8: =IFERROR(LOOKUP(2,1/(Monthly_FX!$E:$E=A8),Monthly_FX!$F:$F),NA()) -> 0.017916166 | C8: =IFERROR(LOOKUP(2,1/(Monthly_FX!$E:$E=A8),Monthly_FX!$G:$G),NA()) -> 0.02350869 | D8: =IFERROR(LOOKUP(2,1/(Monthly_FX!$E:$E=A8),Monthly_FX!$B:$B),NA()) -> 11892.767
A9: 2014Q4 | B9: =IFERROR(LOOKUP(2,1/(Monthly_FX!$E:$E=A9),Monthly_FX!$F:$F),NA()) -> 0.012220506 | C9: =IFERROR(LOOKUP(2,1/(Monthly_FX!$E:$E=A9),Monthly_FX!$G:$G),NA()) -> 0.021151016 | D9: =IFERROR(LOOKUP(2,1/(Monthly_FX!$E:$E=A9),Monthly_FX!$B:$B),NA()) -> 12436.387
A10: 2015Q1 | B10: =IFERROR(LOOKUP(2,1/(Monthly_FX!$E:$E=A10),Monthly_FX!$F:$F),NA()) -> 0.0071444446 | C10: =IFERROR(LOOKUP(2,1/(Monthly_FX!$E:$E=A10),Monthly_FX!$G:$G),NA()) -> 0.013647753 | D10: =IFERROR(LOOKUP(2,1/(Monthly_FX!$E:$E=A10),Monthly_FX!$B:$B),NA()) -> 13063.194
A11: 2015Q2 | B11: =IFERROR(LOOKUP(2,1/(Monthly_FX!$E:$E=A11),Monthly_FX!$F:$F),NA()) -> 0.013347355 | C11: =IFERROR(LOOKUP(2,1/(Monthly_FX!$E:$E=A11),Monthly_FX!$G:$G),NA()) -> 0.013234298 | D11: =IFERROR(LOOKUP(2,1/(Monthly_FX!$E:$E=A11),Monthly_FX!$B:$B),NA()) -> 13311.4
A12: 2015Q3 | B12: =IFERROR(LOOKUP(2,1/(Monthly_FX!$E:$E=A12),Monthly_FX!$F:$F),NA()) -> 0.021039599 | C12: =IFERROR(LOOKUP(2,1/(Monthly_FX!$E:$E=A12),Monthly_FX!$G:$G),NA()) -> 0.014310775 | D12: =IFERROR(LOOKUP(2,1/(Monthly_FX!$E:$E=A12),Monthly_FX!$B:$B),NA()) -> 14407.167
A13: 2015Q4 | B13: =IFERROR(LOOKUP(2,1/(Monthly_FX!$E:$E=A13),Monthly_FX!$F:$F),NA()) -> 0.028549491 | C13: =IFERROR(LOOKUP(2,1/(Monthly_FX!$E:$E=A13),Monthly_FX!$G:$G),NA()) -> 0.0224817 | D13: =IFERROR(LOOKUP(2,1/(Monthly_FX!$E:$E=A13),Monthly_FX!$B:$B),NA()) -> 13842.742
... A52: 2025Q3 | B52: =IFERROR(LOOKUP(2,1/(Monthly_FX!$E:$E=A52),Monthly_FX!$F:$F),NA()) -> 0.0078762447 | C52: =IFERROR(LOOKUP(2,1/(Monthly_FX!$E:$E=A52),Monthly_FX!$G:$G),NA()) -> 0.011515502 | D52: =IFERROR(LOOKUP(2,1/(Monthly_FX!$E:$E=A52),Monthly_FX!$B:$B),NA()) -> 16515.467

Sheet FX_Volatility_Explained
A1: Step-by-step example of FX volatility (log-return based) using small sample data:
A3: Date | B3: IDRUSD | C3: ln(E) | D3: r_t = ln(E_t) - ln(E_{t-1}) | E3: 4-period rolling stdev of r_t
A4: 2025-01-02 | B4: 15500 | C4: ln(E) | D4: r_t | E4: Rolling SD(4)
A5: 2025-01-05 | B5: 15620 | C5: =LN(B5) -> 9.6563074 | E5: =IF(ROW()>=9,_xludf.STDEV.S(OFFSET(D5,-3,0,4,1)),NA()) -> #N/A
A6: 2025-01-06 | B6: 15600 | C6: =LN(B6) -> 9.6550262 | D6: =C6-C5 -> -0.0012812302 | E6: =IF(ROW()>=9,_xludf.STDEV.S(OFFSET(D6,-3,0,4,1)),NA()) -> #N/A
A7: 2025-01-07 | B7: 15710 | C7: =LN(B7) -> 9.6620527 | D7: =C7-C6 -> 0.007026538 | E7: =IF(ROW()>=9,_xludf.STDEV.S(OFFSET(D7,-3,0,4,1)),NA()) -> #N/A
A8: 2025-01-08 | B8: 15680 | C8: =LN(B8) -> 9.6601413 | D8: =C8-C7 -> -0.0019114373 | E8: =IF(ROW()>=9,_xludf.STDEV.S(OFFSET(D8,-3,0,4,1)),NA()) -> #N/A
A9: 2025-01-09 | B9: 15650 | C9: =LN(B9) -> 9.6582262 | D9: =C9-C8 -> -0.0019150979 | E9: =IF(ROW()>=9,_xludf.STDEV.S(OFFSET(D9,-3,0,4,1)),NA()) -> #NAME?
A10: 2025-01-10 | B10: 15730 | C10: =LN(B10) -> 9.663325 | D10: =C10-C9 -> 0.0050988001 | E10: =IF(ROW()>=9,_xludf.STDEV.S(OFFSET(D10,-3,0,4,1)),NA()) -> #NAME?
A11: 2025-01-13 | B11: 15800 | C11: =LN(B11) -> 9.6677652 | D11: =C11-C10 -> 0.004440223 | E11: =IF(ROW()>=9,_xludf.STDEV.S(OFFSET(D11,-3,0,4,1)),NA()) -> #NAME?
C12: =LN(B12) -> #NUM! | D12: =C12-C11 -> #NUM! | E12: =IF(ROW()>=9,_xludf.STDEV.S(OFFSET(D12,-3,0,4,1)),NA()) -> #NAME?
